INFO:alpacarl.meta.log:Logging configured.
ERROR:alpacarl.meta.log:Error connecting to API: request is not authorized
Traceback (most recent call last):
  File "/home/reza_soleymanifar/miniconda3/envs/alpaca-rl/lib/python3.10/site-packages/alpaca_trade_api/rest.py", line 234, in _one_request
    resp.raise_for_status()
  File "/home/reza_soleymanifar/miniconda3/envs/alpaca-rl/lib/python3.10/site-packages/requests/models.py", line 1021, in raise_for_status
    raise HTTPError(http_error_msg, response=self)
requests.exceptions.HTTPError: 401 Client Error: Unauthorized for url: https://api.alpaca.markets/v2/account

During handling of the above exception, another exception occurred:

Traceback (most recent call last):
  File "/home/reza_soleymanifar/repos/AlpacaRL/alpacarl/core/data.py", line 21, in connect
    account_info = self.api.get_account()
  File "/home/reza_soleymanifar/miniconda3/envs/alpaca-rl/lib/python3.10/site-packages/alpaca_trade_api/rest.py", line 276, in get_account
    resp = self.get('/account')
  File "/home/reza_soleymanifar/miniconda3/envs/alpaca-rl/lib/python3.10/site-packages/alpaca_trade_api/rest.py", line 250, in get
    return self._request('GET', path, data)
  File "/home/reza_soleymanifar/miniconda3/envs/alpaca-rl/lib/python3.10/site-packages/alpaca_trade_api/rest.py", line 213, in _request
    return self._one_request(method, url, opts, retry)
  File "/home/reza_soleymanifar/miniconda3/envs/alpaca-rl/lib/python3.10/site-packages/alpaca_trade_api/rest.py", line 242, in _one_request
    raise APIError(error, http_error)
alpaca_trade_api.rest.APIError: request is not authorized
INFO:alpacarl.meta.log:Logging configured.
ERROR:alpacarl.meta.log:Error connecting to API: request is not authorized
Traceback (most recent call last):
  File "/home/reza_soleymanifar/miniconda3/envs/alpaca-rl/lib/python3.10/site-packages/alpaca_trade_api/rest.py", line 234, in _one_request
    resp.raise_for_status()
  File "/home/reza_soleymanifar/miniconda3/envs/alpaca-rl/lib/python3.10/site-packages/requests/models.py", line 1021, in raise_for_status
    raise HTTPError(http_error_msg, response=self)
requests.exceptions.HTTPError: 401 Client Error: Unauthorized for url: https://api.alpaca.markets/v2/account

During handling of the above exception, another exception occurred:

Traceback (most recent call last):
  File "/home/reza_soleymanifar/repos/AlpacaRL/alpacarl/core/data.py", line 21, in connect
    account_info = self.api.get_account()
  File "/home/reza_soleymanifar/miniconda3/envs/alpaca-rl/lib/python3.10/site-packages/alpaca_trade_api/rest.py", line 276, in get_account
    resp = self.get('/account')
  File "/home/reza_soleymanifar/miniconda3/envs/alpaca-rl/lib/python3.10/site-packages/alpaca_trade_api/rest.py", line 250, in get
    return self._request('GET', path, data)
  File "/home/reza_soleymanifar/miniconda3/envs/alpaca-rl/lib/python3.10/site-packages/alpaca_trade_api/rest.py", line 213, in _request
    return self._one_request(method, url, opts, retry)
  File "/home/reza_soleymanifar/miniconda3/envs/alpaca-rl/lib/python3.10/site-packages/alpaca_trade_api/rest.py", line 242, in _one_request
    raise APIError(error, http_error)
alpaca_trade_api.rest.APIError: request is not authorized
INFO:alpacarl.meta.log:Logging configured.
INFO:alpacarl.meta.log:Logging configured.
ERROR:alpacarl.meta.log:Error connecting to API: request is not authorized
Traceback (most recent call last):
  File "/home/reza_soleymanifar/miniconda3/envs/alpaca-rl/lib/python3.10/site-packages/alpaca_trade_api/rest.py", line 234, in _one_request
    resp.raise_for_status()
  File "/home/reza_soleymanifar/miniconda3/envs/alpaca-rl/lib/python3.10/site-packages/requests/models.py", line 1021, in raise_for_status
    raise HTTPError(http_error_msg, response=self)
requests.exceptions.HTTPError: 401 Client Error: Unauthorized for url: https://api.alpaca.markets/v2/account

During handling of the above exception, another exception occurred:

Traceback (most recent call last):
  File "/home/reza_soleymanifar/repos/AlpacaRL/alpacarl/core/data.py", line 21, in connect
    account_info = self.api.get_account()
  File "/home/reza_soleymanifar/miniconda3/envs/alpaca-rl/lib/python3.10/site-packages/alpaca_trade_api/rest.py", line 276, in get_account
    resp = self.get('/account')
  File "/home/reza_soleymanifar/miniconda3/envs/alpaca-rl/lib/python3.10/site-packages/alpaca_trade_api/rest.py", line 250, in get
    return self._request('GET', path, data)
  File "/home/reza_soleymanifar/miniconda3/envs/alpaca-rl/lib/python3.10/site-packages/alpaca_trade_api/rest.py", line 213, in _request
    return self._one_request(method, url, opts, retry)
  File "/home/reza_soleymanifar/miniconda3/envs/alpaca-rl/lib/python3.10/site-packages/alpaca_trade_api/rest.py", line 242, in _one_request
    raise APIError(error, http_error)
alpaca_trade_api.rest.APIError: request is not authorized
INFO:alpacarl.meta.log:Logging configured.
ERROR:alpacarl.meta.log:Error connecting to API: request is not authorized
Traceback (most recent call last):
  File "/home/reza_soleymanifar/miniconda3/envs/alpaca-rl/lib/python3.10/site-packages/alpaca_trade_api/rest.py", line 234, in _one_request
    resp.raise_for_status()
  File "/home/reza_soleymanifar/miniconda3/envs/alpaca-rl/lib/python3.10/site-packages/requests/models.py", line 1021, in raise_for_status
    raise HTTPError(http_error_msg, response=self)
requests.exceptions.HTTPError: 401 Client Error: Unauthorized for url: https://api.alpaca.markets/v2/account

During handling of the above exception, another exception occurred:

Traceback (most recent call last):
  File "/home/reza_soleymanifar/repos/AlpacaRL/alpacarl/core/data.py", line 21, in connect
    account_info = self.api.get_account()
  File "/home/reza_soleymanifar/miniconda3/envs/alpaca-rl/lib/python3.10/site-packages/alpaca_trade_api/rest.py", line 276, in get_account
    resp = self.get('/account')
  File "/home/reza_soleymanifar/miniconda3/envs/alpaca-rl/lib/python3.10/site-packages/alpaca_trade_api/rest.py", line 250, in get
    return self._request('GET', path, data)
  File "/home/reza_soleymanifar/miniconda3/envs/alpaca-rl/lib/python3.10/site-packages/alpaca_trade_api/rest.py", line 213, in _request
    return self._one_request(method, url, opts, retry)
  File "/home/reza_soleymanifar/miniconda3/envs/alpaca-rl/lib/python3.10/site-packages/alpaca_trade_api/rest.py", line 242, in _one_request
    raise APIError(error, http_error)
alpaca_trade_api.rest.APIError: request is not authorized
INFO:alpacarl.meta.log:Logging configured.
INFO:alpacarl.meta.log:Logging configured.
ERROR:alpacarl.meta.log:Error connecting to API: request is not authorized
Traceback (most recent call last):
  File "/home/reza_soleymanifar/miniconda3/envs/alpaca-rl/lib/python3.10/site-packages/alpaca_trade_api/rest.py", line 234, in _one_request
    resp.raise_for_status()
  File "/home/reza_soleymanifar/miniconda3/envs/alpaca-rl/lib/python3.10/site-packages/requests/models.py", line 1021, in raise_for_status
    raise HTTPError(http_error_msg, response=self)
requests.exceptions.HTTPError: 401 Client Error: Unauthorized for url: https://api.alpaca.markets/v2/account

During handling of the above exception, another exception occurred:

Traceback (most recent call last):
  File "/home/reza_soleymanifar/repos/AlpacaRL/alpacarl/core/data.py", line 21, in connect
    account_info = self.api.get_account()
  File "/home/reza_soleymanifar/miniconda3/envs/alpaca-rl/lib/python3.10/site-packages/alpaca_trade_api/rest.py", line 276, in get_account
    resp = self.get('/account')
  File "/home/reza_soleymanifar/miniconda3/envs/alpaca-rl/lib/python3.10/site-packages/alpaca_trade_api/rest.py", line 250, in get
    return self._request('GET', path, data)
  File "/home/reza_soleymanifar/miniconda3/envs/alpaca-rl/lib/python3.10/site-packages/alpaca_trade_api/rest.py", line 213, in _request
    return self._one_request(method, url, opts, retry)
  File "/home/reza_soleymanifar/miniconda3/envs/alpaca-rl/lib/python3.10/site-packages/alpaca_trade_api/rest.py", line 242, in _one_request
    raise APIError(error, http_error)
alpaca_trade_api.rest.APIError: request is not authorized
